Workbook

Sheet 📖マニュアル
A1: 📖 コインランドリー 売上・経費管理ツール 使い方マニュアル
A2: 第3期 2027年5月〜2028年4月 期版 ※黄色セルに入力 / それ以外は自動計算
A4: 📋 シート構成と役割
B5: シート名 | C5: 役割 | D5: 更新頻度
B6: 📊 売上入力 | C6: 機器を行、確認日を列で横スクロール。月ごとにブロック。11回分/月 | D6: 3日ごと
B7: 💴 両替機 | C7: 1,000円札抜取枚数・100円玉補充金額を同じ構成で記録 | D7: 3日ごと
B8: 📈 月次サマリー | C8: 売上入力から月次合計を自動集計。転記不要。 | D8: 自動
B9: 💰 経費・人件費 | C9: 光熱費等の固定費と清掃シフトの記録を入力 | D9: 都度
B10: 📋 損益サマリー | C10: 売上・経費・人件費から月次P&Lを自動計算 | D10: 自動
B11: 📉 ダッシュボード | C11: 年間KPI・月次売上グラフを一覧表示 | D11: 自動
A13: 📊 売上入力シートの使い方
B14: STEP 1 | C14: 鍵を開け、各機器のコイン投入口から現金を機器ごとに抜き取る | D14: 機器別に金額を把握しておく
B15: STEP 2 | C15: 「📅確認日入力」行にその日の日付を入力（M/D形式） | D15: 例：5月8日 → 5/8 第1回・第2回…と右に進む
B16: STEP 3 | C16: 各機器行に抜き取った金額を縦に入力。横にスクロールで月が進む | D16: 月計・年間合計はすべて自動計算
B17: STEP 4 | C17: 各月11回分の枠あり。3日ごとなら月10回なので1回分余裕あり | D17: 月をまたぐときは右の次月ブロックへ
A19: 🎨 セルの色の意味
B20: 🟡 黄色 | C20: 入力セル（日付・金額を入力してください）
B21: ⬜ 白 | C21: 自動計算セル（触らないでください）
B22: 🔵 水色 | C22: 売上・乾燥機中関連
B23: 🩵 水緑 | C23: 乾燥機大関連
B24: 🟣 紫 | C24: 両替機・洗濯乾燥機関連
B25: 🟢 緑 | C25: 経費関連
B26: 🩷 ピンク | C26: 人件費・清掃記録

Sheet 📊売上入力
A1: 🏪 コインランドリー 売上管理台帳 第3期 2027年5月〜2028年4月
A2: 機器名 | B2: 5月 | M2: 5月月計 | N2: 6月 | Y2: 6月月計 | Z2: 7月 | AK2: 7月月計 | AL2: 8月 | AW2: 8月月計 | AX2: 9月 | BI2: 9月月計 | BJ2: 10月 | BU2: 10月月計 | BV2: 11月 | CG2: 11月月計 | CH2: 12月 | CS2: 12月月計 | CT2: 1月 | DE2: 1月月計 | DF2: 2月 | DQ2: 2月月計 | DR2: 3月 | EC2: 3月月計 | ED2: 4月 | EO2: 4月月計 | EP2: 年間合計
A3: 確認日 → | B3: 第1回 | C3: 第2回 | D3: 第3回 | E3: 第4回 | F3: 第5回 | G3: 第6回 | H3: 第7回 | I3: 第8回 | J3: 第9回 | K3: 第10回 | L3: 第11回 | M3: 月計 | N3: 第1回 | O3: 第2回 | P3: 第3回 | Q3: 第4回 | R3: 第5回 | S3: 第6回 | T3: 第7回 | U3: 第8回 | V3: 第9回 | W3: 第10回 | X3: 第11回 | Y3: 月計 | Z3: 第1回 | AA3: 第2回 | AB3: 第3回 | AC3: 第4回 | AD3: 第5回 | AE3: 第6回 | AF3: 第7回 | AG3: 第8回 | AH3: 第9回 | AI3: 第10回 | AJ3: 第11回 | AK3: 月計 | AL3: 第1回 | AM3: 第2回 | AN3: 第3回 | AO3: 第4回 | AP3: 第5回 | AQ3: 第6回 | AR3: 第7回 | AS3: 第8回 | AT3: 第9回 | AU3: 第10回 | AV3: 第11回 | AW3: 月計 | AX3: 第1回 | AY3: 第2回 | AZ3: 第3回 | BA3: 第4回 | BB3: 第5回 | BC3: 第6回 | BD3: 第7回 | BE3: 第8回 | BF3: 第9回 | BG3: 第10回 | BH3: 第11回 | BI3: 月計 | BJ3: 第1回 | BK3: 第2回 | BL3: 第3回 | BM3: 第4回 | BN3: 第5回 | BO3: 第6回 | BP3: 第7回 | BQ3: 第8回 | BR3: 第9回 | BS3: 第10回 | BT3: 第11回 | BU3: 月計 | BV3: 第1回 | BW3: 第2回 | BX3: 第3回 | BY3: 第4回 | BZ3: 第5回 | CA3: 第6回 | CB3: 第7回 | CC3: 第8回 | CD3: 第9回 | CE3: 第10回 | CF3: 第11回 | CG3: 月計 | CH3: 第1回 | CI3: 第2回 | CJ3: 第3回 | CK3: 第4回 | CL3: 第5回 | CM3: 第6回 | CN3: 第7回 | CO3: 第8回 | CP3: 第9回 | CQ3: 第10回 | CR3: 第11回 | CS3: 月計 | CT3: 第1回 | CU3: 第2回 | CV3: 第3回 | CW3: 第4回 | CX3: 第5回 | CY3: 第6回 | CZ3: 第7回 | DA3: 第8回 | DB3: 第9回 | DC3: 第10回 | DD3: 第11回 | DE3: 月計 | DF3: 第1回 | DG3: 第2回 | DH3: 第3回 | DI3: 第4回 | DJ3: 第5回 | DK3: 第6回 | DL3: 第7回 | DM3: 第8回 | DN3: 第9回 | DO3: 第10回 | DP3: 第11回 | DQ3: 月計 | DR3: 第1回 | DS3: 第2回 | DT3: 第3回 | DU3: 第4回 | DV3: 第5回 | DW3: 第6回 | DX3: 第7回 | DY3: 第8回 | DZ3: 第9回 | EA3: 第10回 | EB3: 第11回 | EC3: 月計 | ED3: 第1回 | EE3: 第2回 | EF3: 第3回 | EG3: 第4回 | EH3: 第5回 | EI3: 第6回 | EJ3: 第7回 | EK3: 第8回 | EL3: 第9回 | EM3: 第10回 | EN3: 第11回 | EO3: 月計 | EP3: 年計
A4: 📅 確認日入力 | B4: 46146 | C4: 46150 | D4: 46153 | E4: 46157 | F4: 46160 | G4: 46164 | H4: 46167 | I4: 46171 | J4: 46173 | N4: 46177
A5: 乾燥機(中) No.1&2 | B5: 700 | C5: 3600 | D5: 3000 | E5: 1500 | F5: 1000 | G5: 600 | H5: 1300 | I5: 400 | J5: 2500 | M5: =SUM(B5:L5) -> 14600 | N5: 1300 | Y5: =SUM(N5:X5) -> 1300 | AK5: =SUM(Z5:AJ5) -> 0 | AW5: =SUM(AL5:AV5) -> 0 | BI5: =SUM(AX5:BH5) -> 0 | BU5: =SUM(BJ5:BT5) -> 0 | CG5: =SUM(BV5:CF5) -> 0 | CS5: =SUM(CH5:CR5) -> 0 | DE5: =SUM(CT5:DD5) -> 0 | DQ5: =SUM(DF5:DP5) -> 0 | EC5: =SUM(DR5:EB5) -> 0 | EO5: =SUM(ED5:EN5) -> 0 | EP5: =M5+Y5+AK5+AW5+BI5+BU5+CG5+CS5+DE5+DQ5+EC5+EO5 -> 15900
A6: 乾燥機(中) No.3&4 | B6: 3100 | C6: 4900 | D6: 5300 | E6: 6100 | F6: 3100 | G6: 1100 | H6: 1800 | I6: 1100 | J6: 3600 | M6: =SUM(B6:L6) -> 30100 | N6: 1600 | Y6: =SUM(N6:X6) -> 1600 | AK6: =SUM(Z6:AJ6) -> 0 | AW6: =SUM(AL6:AV6) -> 0 | BI6: =SUM(AX6:BH6) -> 0 | BU6: =SUM(BJ6:BT6) -> 0 | CG6: =SUM(BV6:CF6) -> 0 | CS6: =SUM(CH6:CR6) -> 0 | DE6: =SUM(CT6:DD6) -> 0 | DQ6: =SUM(DF6:DP6) -> 0 | EC6: =SUM(DR6:EB6) -> 0 | EO6: =SUM(ED6:EN6) -> 0 | EP6: =M6+Y6+AK6+AW6+BI6+BU6+CG6+CS6+DE6+DQ6+EC6+EO6 -> 31700
A7: 乾燥機(中) No.5&6 | B7: 3600 | C7: 5000 | D7: 7600 | E7: 5400 | F7: 3900 | G7: 3500 | H7: 5700 | I7: 4700 | J7: 2400 | M7: =SUM(B7:L7) -> 41800 | N7: 3100 | Y7: =SUM(N7:X7) -> 3100 | AK7: =SUM(Z7:AJ7) -> 0 | AW7: =SUM(AL7:AV7) -> 0 | BI7: =SUM(AX7:BH7) -> 0 | BU7: =SUM(BJ7:BT7) -> 0 | CG7: =SUM(BV7:CF7) -> 0 | CS7: =SUM(CH7:CR7) -> 0 | DE7: =SUM(CT7:DD7) -> 0 | DQ7: =SUM(DF7:DP7) -> 0 | EC7: =SUM(DR7:EB7) -> 0 | EO7: =SUM(ED7:EN7) -> 0 | EP7: =M7+Y7+AK7+AW7+BI7+BU7+CG7+CS7+DE7+DQ7+EC7+EO7 -> 44900
A8: 乾燥機(中) No.7&8 | B8: 1000 | C8: 8900 | D8: 5600 | E8: 9700 | F8: 7100 | G8: 5900 | H8: 4200 | I8: 7500 | J8: 5800 | M8: =SUM(B8:L8) -> 55700 | N8: 4900 | Y8: =SUM(N8:X8) -> 4900 | AK8: =SUM(Z8:AJ8) -> 0 | AW8: =SUM(AL8:AV8) -> 0 | BI8: =SUM(AX8:BH8) -> 0 | BU8: =SUM(BJ8:BT8) -> 0 | CG8: =SUM(BV8:CF8) -> 0 | CS8: =SUM(CH8:CR8) -> 0 | DE8: =SUM(CT8:DD8) -> 0 | DQ8: =SUM(DF8:DP8) -> 0 | EC8: =SUM(DR8:EB8) -> 0 | EO8: =SUM(ED8:EN8) -> 0 | EP8: =M8+Y8+AK8+AW8+BI8+BU8+CG8+CS8+DE8+DQ8+EC8+EO8 -> 60600
A9: 乾燥機(中) No.9&10 | B9: 6800 | C9: 10600 | D9: 7600 | E9: 3200 | F9: 2900 | G9: 6200 | H9: 4600 | I9: 4500 | J9: 3300 | M9: =SUM(B9:L9) -> 49700 | N9: 5500 | Y9: =SUM(N9:X9) -> 5500 | AK9: =SUM(Z9:AJ9) -> 0 | AW9: =SUM(AL9:AV9) -> 0 | BI9: =SUM(AX9:BH9) -> 0 | BU9: =SUM(BJ9:BT9) -> 0 | CG9: =SUM(BV9:CF9) -> 0 | CS9: =SUM(CH9:CR9) -> 0 | DE9: =SUM(CT9:DD9) -> 0 | DQ9: =SUM(DF9:DP9) -> 0 | EC9: =SUM(DR9:EB9) -> 0 | EO9: =SUM(ED9:EN9) -> 0 | EP9: =M9+Y9+AK9+AW9+BI9+BU9+CG9+CS9+DE9+DQ9+EC9+EO9 -> 55200
A10: 乾燥機(大) No.11 | B10: 1000 | C10: 4100 | D10: 3700 | E10: 4900 | F10: 1200 | G10: 2600 | H10: 2000 | I10: 3400 | J10: 2500 | M10: =SUM(B10:L10) -> 25400 | N10: 3300 | Y10: =SUM(N10:X10) -> 3300 | AK10: =SUM(Z10:AJ10) -> 0 | AW10: =SUM(AL10:AV10) -> 0 | BI10: =SUM(AX10:BH10) -> 0 | BU10: =SUM(BJ10:BT10) -> 0 | CG10: =SUM(BV10:CF10) -> 0 | CS10: =SUM(CH10:CR10) -> 0 | DE10: =SUM(CT10:DD10) -> 0 | DQ10: =SUM(DF10:DP10) -> 0 | EC10: =SUM(DR10:EB10) -> 0 | EO10: =SUM(ED10:EN10) -> 0 | EP10: =M10+Y10+AK10+AW10+BI10+BU10+CG10+CS10+DE10+DQ10+EC10+EO10 -> 28700
A11: 乾燥機(大) No.12 | B11: 1600 | C11: 1700 | D11: 1900 | E11: 1400 | F11: 0 | G11: 700 | H11: 1000 | I11: 1700 | J11: 400 | M11: =SUM(B11:L11) -> 10400 | N11: 1700 | Y11: =SUM(N11:X11) -> 1700 | AK11: =SUM(Z11:AJ11) -> 0 | AW11: =SUM(AL11:AV11) -> 0 | BI11: =SUM(AX11:BH11) -> 0 | BU11: =SUM(BJ11:BT11) -> 0 | CG11: =SUM(BV11:CF11) -> 0 | CS11: =SUM(CH11:CR11) -> 0 | DE11: =SUM(CT11:DD11) -> 0 | DQ11: =SUM(DF11:DP11) -> 0 | EC11: =SUM(DR11:EB11) -> 0 | EO11: =SUM(ED11:EN11) -> 0 | EP11: =M11+Y11+AK11+AW11+BI11+BU11+CG11+CS11+DE11+DQ11+EC11+EO11 -> 12100
A12: 洗濯乾燥機 No.13 | B12: 21200 | C12: 20100 | D12: 12600 | E12: 19600 | F12: 15700 | G12: 19600 | H12: 11600 | I12: 18400 | J12: 14000 | M12: =SUM(B12:L12) -> 152800 | N12: 19300 | Y12: =SUM(N12:X12) -> 19300 | AK12: =SUM(Z12:AJ12) -> 0 | AW12: =SUM(AL12:AV12) -> 0 | BI12: =SUM(AX12:BH12) -> 0 | BU12: =SUM(BJ12:BT12) -> 0 | CG12: =SUM(BV12:CF12) -> 0 | CS12: =SUM(CH12:CR12) -> 0 | DE12: =SUM(CT12:DD12) -> 0 | DQ12: =SUM(DF12:DP12) -> 0 | EC12: =SUM(DR12:EB12) -> 0 | EO12: =SUM(ED12:EN12) -> 0 | EP12: =M12+Y12+AK12+AW12+BI12+BU12+CG12+CS12+DE12+DQ12+EC12+EO12 -> 172100
A13: 📌 確認日合計 | B13: =SUM(B5:B12) -> 39000 | C13: =SUM(C5:C12) -> 58900 | D13: =SUM(D5:D12) -> 47300 | E13: =SUM(E5:E12) -> 51800 | F13: =SUM(F5:F12) -> 34900 | G13: =SUM(G5:G12) -> 40200 | H13: =SUM(H5:H12) -> 32200 | I13: =SUM(I5:I12) -> 41700 | ... L13: =SUM(L5:L12) -> 0 | M13: =SUM(B13:L13) -> 380500 | N13: =SUM(N5:N12) -> 40700 | O13: =SUM(O5:O12) -> 0 | P13: =SUM(P5:P12) -> 0 | Q13: =SUM(Q5:Q12) -> 0 | R13: =SUM(R5:R12) -> 0 | S13: =SUM(S5:S12) -> 0 | T13: =SUM(T5:T12) -> 0 | U13: =SUM(U5:U12) -> 0 | ... X13: =SUM(X5:X12) -> 0 | Y13: =SUM(N13:X13) -> 40700 | Z13: =SUM(Z5:Z12) -> 0 | AA13: =SUM(AA5:AA12) -> 0 | AB13: =SUM(AB5:AB12) -> 0 | AC13: =SUM(AC5:AC12) -> 0 | AD13: =SUM(AD5:AD12) -> 0 | AE13: =SUM(AE5:AE12) -> 0 | AF13: =SUM(AF5:AF12) -> 0 | AG13: =SUM(AG5:AG12) -> 0 | ... AJ13: =SUM(AJ5:AJ12) -> 0 | AK13: =SUM(Z13:AJ13) -> 0 | AL13: =SUM(AL5:AL12) -> 0 | AM13: =SUM(AM5:AM12) -> 0 | AN13: =SUM(AN5:AN12) -> 0 | AO13: =SUM(AO5:AO12) -> 0 | AP13: =SUM(AP5:AP12) -> 0 | AQ13: =SUM(AQ5:AQ12) -> 0 | AR13: =SUM(AR5:AR12) -> 0 | AS13: =SUM(AS5:AS12) -> 0 | ... AV13: =SUM(AV5:AV12) -> 0 | AW13: =SUM(AL13:AV13) -> 0 | AX13: =SUM(AX5:AX12) -> 0 | AY13: =SUM(AY5:AY12) -> 0 | AZ13: =SUM(AZ5:AZ12) -> 0 | BA13: =SUM(BA5:BA12) -> 0 | BB13: =SUM(BB5:BB12) -> 0 | BC13: =SUM(BC5:BC12) -> 0 | BD13: =SUM(BD5:BD12) -> 0 | BE13: =SUM(BE5:BE12) -> 0 | ... BH13: =SUM(BH5:BH12) -> 0 | BI13: =SUM(AX13:BH13) -> 0 | BJ13: =SUM(BJ5:BJ12) -> 0 | BK13: =SUM(BK5:BK12) -> 0 | BL13: =SUM(BL5:BL12) -> 0 | BM13: =SUM(BM5:BM12) -> 0 | BN13: =SUM(BN5:BN12) -> 0 | BO13: =SUM(BO5:BO12) -> 0 | BP13: =SUM(BP5:BP12) -> 0 | BQ13: =SUM(BQ5:BQ12) -> 0 | ... BT13: =SUM(BT5:BT12) -> 0 | BU13: =SUM(BJ13:BT13) -> 0 | BV13: =SUM(BV5:BV12) -> 0 | BW13: =SUM(BW5:BW12) -> 0 | BX13: =SUM(BX5:BX12) -> 0 | BY13: =SUM(BY5:BY12) -> 0 | BZ13: =SUM(BZ5:BZ12) -> 0 | CA13: =SUM(CA5:CA12) -> 0 | CB13: =SUM(CB5:CB12) -> 0 | CC13: =SUM(CC5:CC12) -> 0 | ... CF13: =SUM(CF5:CF12) -> 0 | CG13: =SUM(BV13:CF13) -> 0 | CH13: =SUM(CH5:CH12) -> 0 | CI13: =SUM(CI5:CI12) -> 0 | CJ13: =SUM(CJ5:CJ12) -> 0 | CK13: =SUM(CK5:CK12) -> 0 | CL13: =SUM(CL5:CL12) -> 0 | CM13: =SUM(CM5:CM12) -> 0 | CN13: =SUM(CN5:CN12) -> 0 | CO13: =SUM(CO5:CO12) -> 0 | ... CR13: =SUM(CR5:CR12) -> 0 | CS13: =SUM(CH13:CR13) -> 0 | CT13: =SUM(CT5:CT12) -> 0 | CU13: =SUM(CU5:CU12) -> 0 | CV13: =SUM(CV5:CV12) -> 0 | CW13: =SUM(CW5:CW12) -> 0 | CX13: =SUM(CX5:CX12) -> 0 | CY13: =SUM(CY5:CY12) -> 0 | CZ13: =SUM(CZ5:CZ12) -> 0 | DA13: =SUM(DA5:DA12) -> 0 | ... DD13: =SUM(DD5:DD12) -> 0 | DE13: =SUM(CT13:DD13) -> 0 | DF13: =SUM(DF5:DF12) -> 0 | DG13: =SUM(DG5:DG12) -> 0 | DH13: =SUM(DH5:DH12) -> 0 | DI13: =SUM(DI5:DI12) -> 0 | DJ13: =SUM(DJ5:DJ12) -> 0 | DK13: =SUM(DK5:DK12) -> 0 | DL13: =SUM(DL5:DL12) -> 0 | DM13: =SUM(DM5:DM12) -> 0 | ... DP13: =SUM(DP5:DP12) -> 0 | DQ13: =SUM(DF13:DP13) -> 0 | DR13: =SUM(DR5:DR12) -> 0 | DS13: =SUM(DS5:DS12) -> 0 | DT13: =SUM(DT5:DT12) -> 0 | DU13: =SUM(DU5:DU12) -> 0 | DV13: =SUM(DV5:DV12) -> 0 | DW13: =SUM(DW5:DW12) -> 0 | DX13: =SUM(DX5:DX12) -> 0 | DY13: =SUM(DY5:DY12) -> 0 | ... EB13: =SUM(EB5:EB12) -> 0 | EC13: =SUM(DR13:EB13) -> 0 | ED13: =SUM(ED5:ED12) -> 0 | EE13: =SUM(EE5:EE12) -> 0 | EF13: =SUM(EF5:EF12) -> 0 | EG13: =SUM(EG5:EG12) -> 0 | EH13: =SUM(EH5:EH12) -> 0 | EI13: =SUM(EI5:EI12) -> 0 | EJ13: =SUM(EJ5:EJ12) -> 0 | EK13: =SUM(EK5:EK12) -> 0 | ... EN13: =SUM(EN5:EN12) -> 0 | EO13: =SUM(ED13:EN13) -> 0 | EP13: =M13+Y13+AK13+AW13+BI13+BU13+CG13+CS13+DE13+DQ13+EC13+EO13 -> 421200
A14: 💴 両替機 管理記録（確認日は上の行と共通）
A15: 💴 1,000円札 抜取（枚） | B15: 32 | C15: 65 | D15: 30 | E15: 30 | F15: 28 | G15: 35 | H15: 30 | I15: 33 | J15: 30 | M15: =SUM(B15:L15) -> 313 | N15: 40 | Y15: =SUM(N15:X15) -> 40 | AK15: =SUM(Z15:AJ15) -> 0 | AW15: =SUM(AL15:AV15) -> 0 | BI15: =SUM(AX15:BH15) -> 0 | BU15: =SUM(BJ15:BT15) -> 0 | CG15: =SUM(BV15:CF15) -> 0 | CS15: =SUM(CH15:CR15) -> 0 | DE15: =SUM(CT15:DD15) -> 0 | DQ15: =SUM(DF15:DP15) -> 0 | EC15: =SUM(DR15:EB15) -> 0 | EO15: =SUM(ED15:EN15) -> 0 | EP15: =M15+Y15+AK15+AW15+BI15+BU15+CG15+CS15+DE15+DQ15+EC15+EO15 -> 353
A16: └ 抜取金額（自動） | B16: =IF(B15<>"",B15*1000,"") -> 32000 | C16: =IF(C15<>"",C15*1000,"") -> 65000 | D16: =IF(D15<>"",D15*1000,"") -> 30000 | E16: =IF(E15<>"",E15*1000,"") -> 30000 | F16: =IF(F15<>"",F15*1000,"") -> 28000 | G16: =IF(G15<>"",G15*1000,"") -> 35000 | H16: =IF(H15<>"",H15*1000,"") -> 30000 | I16: =IF(I15<>"",I15*1000,"") -> 33000 | ... L16: =IF(L15<>"",L15*1000,"") | M16: =SUM(B16:L16) -> 313000 | N16: =IF(N15<>"",N15*1000,"") -> 40000 | O16: =IF(O15<>"",O15*1000,"") | P16: =IF(P15<>"",P15*1000,"") | Q16: =IF(Q15<>"",Q15*1000,"") | R16: =IF(R15<>"",R15*1000,"") | S16: =IF(S15<>"",S15*1000,"") | T16: =IF(T15<>"",T15*1000,"") | U16: =IF(U15<>"",U15*1000,"") | ... X16: =IF(X15<>"",X15*1000,"") | Y16: =SUM(N16:X16) -> 40000 | Z16: =IF(Z15<>"",Z15*1000,"") | AA16: =IF(AA15<>"",AA15*1000,"") | AB16: =IF(AB15<>"",AB15*1000,"") | AC16: =IF(AC15<>"",AC15*1000,"") | AD16: =IF(AD15<>"",AD15*1000,"") | AE16: =IF(AE15<>"",AE15*1000,"") | AF16: =IF(AF15<>"",AF15*1000,"") | AG16: =IF(AG15<>"",AG15*1000,"") | ... AJ16: =IF(AJ15<>"",AJ15*1000,"") | AK16: =SUM(Z16:AJ16) -> 0 | AL16: =IF(AL15<>"",AL15*1000,"") | AM16: =IF(AM15<>"",AM15*1000,"") | AN16: =IF(AN15<>"",AN15*1000,"") | AO16: =IF(AO15<>"",AO15*1000,"") | AP16: =IF(AP15<>"",AP15*1000,"") | AQ16: =IF(AQ15<>"",AQ15*1000,"") | AR16: =IF(AR15<>"",AR15*1000,"") | AS16: =IF(AS15<>"",AS15*1000,"") | ... AV16: =IF(AV15<>"",AV15*1000,"") | AW16: =SUM(AL16:AV16) -> 0 | AX16: =IF(AX15<>"",AX15*1000,"") | AY16: =IF(AY15<>"",AY15*1000,"") | AZ16: =IF(AZ15<>"",AZ15*1000,"") | BA16: =IF(BA15<>"",BA15*1000,"") | BB16: =IF(BB15<>"",BB15*1000,"") | BC16: =IF(BC15<>"",BC15*1000,"") | BD16: =IF(BD15<>"",BD15*1000,"") | BE16: =IF(BE15<>"",BE15*1000,"") | ... BH16: =IF(BH15<>"",BH15*1000,"") | BI16: =SUM(AX16:BH16) -> 0 | BJ16: =IF(BJ15<>"",BJ15*1000,"") | BK16: =IF(BK15<>"",BK15*1000,"") | BL16: =IF(BL15<>"",BL15*1000,"") | BM16: =IF(BM15<>"",BM15*1000,"") | BN16: =IF(BN15<>"",BN15*1000,"") | BO16: =IF(BO15<>"",BO15*1000,"") | BP16: =IF(BP15<>"",BP15*1000,"") | BQ16: =IF(BQ15<>"",BQ15*1000,"") | ... BT16: =IF(BT15<>"",BT15*1000,"") | BU16: =SUM(BJ16:BT16) -> 0 | BV16: =IF(BV15<>"",BV15*1000,"") | BW16: =IF(BW15<>"",BW15*1000,"") | BX16: =IF(BX15<>"",BX15*1000,"") | BY16: =IF(BY15<>"",BY15*1000,"") | BZ16: =IF(BZ15<>"",BZ15*1000,"") | CA16: =IF(CA15<>"",CA15*1000,"") | CB16: =IF(CB15<>"",CB15*1000,"") | CC16: =IF(CC15<>"",CC15*1000,"") | ... CF16: =IF(CF15<>"",CF15*1000,"") | CG16: =SUM(BV16:CF16) -> 0 | CH16: =IF(CH15<>"",CH15*1000,"") | CI16: =IF(CI15<>"",CI15*1000,"") | CJ16: =IF(CJ15<>"",CJ15*1000,"") | CK16: =IF(CK15<>"",CK15*1000,"") | CL16: =IF(CL15<>"",CL15*1000,"") | CM16: =IF(CM15<>"",CM15*1000,"") | CN16: =IF(CN15<>"",CN15*1000,"") | CO16: =IF(CO15<>"",CO15*1000,"") | ... CR16: =IF(CR15<>"",CR15*1000,"") | CS16: =SUM(CH16:CR16) -> 0 | CT16: =IF(CT15<>"",CT15*1000,"") | CU16: =IF(CU15<>"",CU15*1000,"") | CV16: =IF(CV15<>"",CV15*1000,"") | CW16: =IF(CW15<>"",CW15*1000,"") | CX16: =IF(CX15<>"",CX15*1000,"") | CY16: =IF(CY15<>"",CY15*1000,"") | CZ16: =IF(CZ15<>"",CZ15*1000,"") | DA16: =IF(DA15<>"",DA15*1000,"") | ... DD16: =IF(DD15<>"",DD15*1000,"") | DE16: =SUM(CT16:DD16) -> 0 | DF16: =IF(DF15<>"",DF15*1000,"") | DG16: =IF(DG15<>"",DG15*1000,"") | DH16: =IF(DH15<>"",DH15*1000,"") | DI16: =IF(DI15<>"",DI15*1000,"") | DJ16: =IF(DJ15<>"",DJ15*1000,"") | DK16: =IF(DK15<>"",DK15*1000,"") | DL16: =IF(DL15<>"",DL15*1000,"") | DM16: =IF(DM15<>"",DM15*1000,"") | ... DP16: =IF(DP15<>"",DP15*1000,"") | DQ16: =SUM(DF16:DP16) -> 0 | DR16: =IF(DR15<>"",DR15*1000,"") | DS16: =IF(DS15<>"",DS15*1000,"") | DT16: =IF(DT15<>"",DT15*1000,"") | DU16: =IF(DU15<>"",DU15*1000,"") | DV16: =IF(DV15<>"",DV15*1000,"") | DW16: =IF(DW15<>"",DW15*1000,"") | DX16: =IF(DX15<>"",DX15*1000,"") | DY16: =IF(DY15<>"",DY15*1000,"") | ... EB16: =IF(EB15<>"",EB15*1000,"") | EC16: =SUM(DR16:EB16) -> 0 | ED16: =IF(ED15<>"",ED15*1000,"") | EE16: =IF(EE15<>"",EE15*1000,"") | EF16: =IF(EF15<>"",EF15*1000,"") | EG16: =IF(EG15<>"",EG15*1000,"") | EH16: =IF(EH15<>"",EH15*1000,"") | EI16: =IF(EI15<>"",EI15*1000,"") | EJ16: =IF(EJ15<>"",EJ15*1000,"") | EK16: =IF(EK15<>"",EK15*1000,"") | ... EN16: =IF(EN15<>"",EN15*1000,"") | EO16: =SUM(ED16:EN16) -> 0 | EP16: =M16+Y16+AK16+AW16+BI16+BU16+CG16+CS16+DE16+DQ16+EC16+EO16 -> 353000

Sheet 📉ダッシュボード
A1: 📉 ダッシュボード 第3期 2027年5月〜2028年4月
A3: 年間売上合計 | D3: 年間営業利益 | H3: 年間利益率
A4: ='📊売上入力'!EP13 -> 421200 | D4: ='📋損益サマリー'!E14 -> 0 | H4: ='📋損益サマリー'!E15 -> 0
A6: 📊 月次売上・利益推移
A7: 月 | B7: 売上 | C7: 営業利益
A8: 46143 | B8: ='📈月次サマリー'!E4 -> 380500 | C8: ='📋損益サマリー'!C14 -> 357601.67
A9: 46174 | B9: ='📈月次サマリー'!E5 -> 40700 | C9: ='📋損益サマリー'!D14 -> 35878.333
A10: 46204 | B10: ='📈月次サマリー'!E6 -> 0 | C10: ='📋損益サマリー'!E14 -> 0
A11: 46235 | B11: ='📈月次サマリー'!E7 -> 0 | C11: ='📋損益サマリー'!F14 -> 0
A12: 46266 | B12: ='📈月次サマリー'!E8 -> 0 | C12: ='📋損益サマリー'!G14 -> 0
A13: 46296 | B13: ='📈月次サマリー'!E9 -> 0 | C13: ='📋損益サマリー'!H14 -> 0
A14: 46327 | B14: ='📈月次サマリー'!E10 -> 0 | C14: ='📋損益サマリー'!I14 -> 0
A15: 46357 | B15: ='📈月次サマリー'!E11 -> 0 | C15: ='📋損益サマリー'!J14 -> 0
A16: 46388 | B16: ='📈月次サマリー'!E12 -> 0 | C16: ='📋損益サマリー'!K14 -> 0
A17: 46419 | B17: ='📈月次サマリー'!E13 -> 0 | C17: ='📋損益サマリー'!L14 -> 0
A18: 46447 | B18: ='📈月次サマリー'!E14 -> 0 | C18: ='📋損益サマリー'!M14 -> 0
A19: 46478 | B19: ='📈月次サマリー'!E15 -> 0 | C19: ='📋損益サマリー'!N14 -> 0
A22: 🔧 機器別 稼働率サマリー
A23: 機器名 | B23: 合計売上 | C23: 合計回数 | D23: 年間平均稼働率 | E23: 評価
A24: 乾燥機(中) No.1&6 | B24: ='🔧稼働率分析'!AL13 -> 15900 | C24: ='🔧稼働率分析'!AM13 -> 53 | D24: ='🔧稼働率分析'!AN13 -> 0.0049604656 | E24: ='🔧稼働率分析'!AO13 -> 🔴 要改善
A25: 乾燥機(中) No.2&7 | B25: ='🔧稼働率分析'!AL14 -> 31700 | C25: ='🔧稼働率分析'!AM14 -> 105.66667 | D25: ='🔧稼働率分析'!AN14 -> 0.0098794471 | E25: ='🔧稼働率分析'!AO14 -> 🔴 要改善
A26: 乾燥機(中) No.3&8 | B26: ='🔧稼働率分析'!AL15 -> 44900 | C26: ='🔧稼働率分析'!AM15 -> 149.66667 | D26: ='🔧稼働率分析'!AN15 -> 0.014001933 | E26: ='🔧稼働率分析'!AO15 -> 🔴 要改善
A27: 乾燥機(中) No.4&9 | B27: ='🔧稼働率分析'!AL16 -> 60600 | C27: ='🔧稼働率分析'!AM16 -> 202 | D27: ='🔧稼働率分析'!AN16 -> 0.018905358 | E27: ='🔧稼働率分析'!AO16 -> 🔴 要改善
A28: 乾燥機(中) No.5&10 | B28: ='🔧稼働率分析'!AL17 -> 55200 | C28: ='🔧稼働率分析'!AM17 -> 184 | D28: ='🔧稼働率分析'!AN17 -> 0.017231473 | E28: ='🔧稼働率分析'!AO17 -> 🔴 要改善
A29: 乾燥機(大) No.1 | B29: ='🔧稼働率分析'!AL18 -> 28700 | C29: ='🔧稼働率分析'!AM18 -> 95.666667 | D29: ='🔧稼働率分析'!AN18 -> 0.0078880426 | E29: ='🔧稼働率分析'!AO18 -> 🔴 要改善
A30: 乾燥機(大) No.2 | B30: ='🔧稼働率分析'!AL19 -> 12100 | C30: ='🔧稼働率分析'!AM19 -> 40.333333 | D30: ='🔧稼働率分析'!AN19 -> 0.0033284382 | E30: ='🔧稼働率分析'!AO19 -> 🔴 要改善
A31: 洗濯乾燥機 No.1 | B31: ='🔧稼働率分析'!AL20 -> 172100 | C31: ='🔧稼働率分析'!AM20 -> 149.65217 | D31: ='🔧稼働率分析'!AN20 -> 0.02299386 | E31: ='🔧稼働率分析'!AO20 -> 🔴 要改善
A32: 📌 全機器平均 | B32: ='🔧稼働率分析'!AJ21 -> 0 | C32: ='🔧稼働率分析'!G20 -> 0.031855878 | D32: ='🔧稼働率分析'!J20 -> 0

Sheet 📈月次サマリー
A1: 📈 月次サマリー 第3期 2027年5月〜2028年4月
A3: 月 | B3: 乾燥機(中) | C3: 乾燥機(大) | D3: 洗濯乾燥機 | E3: 月次売上合計 | F3: 両替機抜取 | G3: 前月比 | H3: 稼働率(推定)
A4: 46143 | B4: ='📊売上入力'!M5+'📊売上入力'!M6+'📊売上入力'!M7+'📊売上入力'!M8+'📊売上入力'!M9 -> 191900 | C4: ='📊売上入力'!M10+'📊売上入力'!M11 -> 35800 | D4: ='📊売上入力'!M12 -> 152800 | E4: ='📊売上入力'!M13 -> 380500 | F4: ='📊売上入力'!M16 -> 313000 | G4: — | H4: ='🔧稼働率分析'!D21 -> 0.13477068
A5: 46174 | B5: ='📊売上入力'!Y5+'📊売上入力'!Y6+'📊売上入力'!Y7+'📊売上入力'!Y8+'📊売上入力'!Y9 -> 16400 | C5: ='📊売上入力'!Y10+'📊売上入力'!Y11 -> 5000 | D5: ='📊売上入力'!Y12 -> 19300 | E5: ='📊売上入力'!Y13 -> 40700 | F5: ='📊売上入力'!Y16 -> 40000 | G5: =IFERROR(E5/E4-1,"—") -> -0.89303548 | H5: ='🔧稼働率分析'!G21 -> 0.014012849
A6: 46204 | B6: ='📊売上入力'!AK5+'📊売上入力'!AK6+'📊売上入力'!AK7+'📊売上入力'!AK8+'📊売上入力'!AK9 -> 0 | C6: ='📊売上入力'!AK10+'📊売上入力'!AK11 -> 0 | D6: ='📊売上入力'!AK12 -> 0 | E6: ='📊売上入力'!AK13 -> 0 | F6: ='📊売上入力'!AK16 -> 0 | G6: =IFERROR(E6/E5-1,"—") -> -1 | H6: ='🔧稼働率分析'!J21 -> 0
A7: 46235 | B7: ='📊売上入力'!AW5+'📊売上入力'!AW6+'📊売上入力'!AW7+'📊売上入力'!AW8+'📊売上入力'!AW9 -> 0 | C7: ='📊売上入力'!AW10+'📊売上入力'!AW11 -> 0 | D7: ='📊売上入力'!AW12 -> 0 | E7: ='📊売上入力'!AW13 -> 0 | F7: ='📊売上入力'!AW16 -> 0 | G7: =IFERROR(E7/E6-1,"—") -> — | H7: ='🔧稼働率分析'!M21 -> 0
A8: 46266 | B8: ='📊売上入力'!BI5+'📊売上入力'!BI6+'📊売上入力'!BI7+'📊売上入力'!BI8+'📊売上入力'!BI9 -> 0 | C8: ='📊売上入力'!BI10+'📊売上入力'!BI11 -> 0 | D8: ='📊売上入力'!BI12 -> 0 | E8: ='📊売上入力'!BI13 -> 0 | F8: ='📊売上入力'!BI16 -> 0 | G8: =IFERROR(E8/E7-1,"—") -> — | H8: ='🔧稼働率分析'!P21 -> 0
A9: 46296 | B9: ='📊売上入力'!BU5+'📊売上入力'!BU6+'📊売上入力'!BU7+'📊売上入力'!BU8+'📊売上入力'!BU9 -> 0 | C9: ='📊売上入力'!BU10+'📊売上入力'!BU11 -> 0 | D9: ='📊売上入力'!BU12 -> 0 | E9: ='📊売上入力'!BU13 -> 0 | F9: ='📊売上入力'!BU16 -> 0 | G9: =IFERROR(E9/E8-1,"—") -> — | H9: ='🔧稼働率分析'!S21 -> 0
A10: 46327 | B10: ='📊売上入力'!CG5+'📊売上入力'!CG6+'📊売上入力'!CG7+'📊売上入力'!CG8+'📊売上入力'!CG9 -> 0 | C10: ='📊売上入力'!CG10+'📊売上入力'!CG11 -> 0 | D10: ='📊売上入力'!CG12 -> 0 | E10: ='📊売上入力'!CG13 -> 0 | F10: ='📊売上入力'!CG16 -> 0 | G10: =IFERROR(E10/E9-1,"—") -> — | H10: ='🔧稼働率分析'!V21 -> 0
A11: 46357 | B11: ='📊売上入力'!CS5+'📊売上入力'!CS6+'📊売上入力'!CS7+'📊売上入力'!CS8+'📊売上入力'!CS9 -> 0 | C11: ='📊売上入力'!CS10+'📊売上入力'!CS11 -> 0 | D11: ='📊売上入力'!CS12 -> 0 | E11: ='📊売上入力'!CS13 -> 0 | F11: ='📊売上入力'!CS16 -> 0 | G11: =IFERROR(E11/E10-1,"—") -> — | H11: ='🔧稼働率分析'!Y21 -> 0
A12: 46388 | B12: ='📊売上入力'!DE5+'📊売上入力'!DE6+'📊売上入力'!DE7+'📊売上入力'!DE8+'📊売上入力'!DE9 -> 0 | C12: ='📊売上入力'!DE10+'📊売上入力'!DE11 -> 0 | D12: ='📊売上入力'!DE12 -> 0 | E12: ='📊売上入力'!DE13 -> 0 | F12: ='📊売上入力'!DE16 -> 0 | G12: =IFERROR(E12/E11-1,"—") -> — | H12: ='🔧稼働率分析'!AB21 -> 0
A13: 46419 | B13: ='📊売上入力'!DQ5+'📊売上入力'!DQ6+'📊売上入力'!DQ7+'📊売上入力'!DQ8+'📊売上入力'!DQ9 -> 0 | C13: ='📊売上入力'!DQ10+'📊売上入力'!DQ11 -> 0 | D13: ='📊売上入力'!DQ12 -> 0 | E13: ='📊売上入力'!DQ13 -> 0 | F13: ='📊売上入力'!DQ16 -> 0 | G13: =IFERROR(E13/E12-1,"—") -> — | H13: ='🔧稼働率分析'!AE21 -> 0
A14: 46447 | B14: ='📊売上入力'!EC5+'📊売上入力'!EC6+'📊売上入力'!EC7+'📊売上入力'!EC8+'📊売上入力'!EC9 -> 0 | C14: ='📊売上入力'!EC10+'📊売上入力'!EC11 -> 0 | D14: ='📊売上入力'!EC12 -> 0 | E14: ='📊売上入力'!EC13 -> 0 | F14: ='📊売上入力'!EC16 -> 0 | G14: =IFERROR(E14/E13-1,"—") -> — | H14: ='🔧稼働率分析'!AH21 -> 0
A15: 46478 | B15: ='📊売上入力'!EO5+'📊売上入力'!EO6+'📊売上入力'!EO7+'📊売上入力'!EO8+'📊売上入力'!EO9 -> 0 | C15: ='📊売上入力'!EO10+'📊売上入力'!EO11 -> 0 | D15: ='📊売上入力'!EO12 -> 0 | E15: ='📊売上入力'!EO13 -> 0 | F15: ='📊売上入力'!EO16 -> 0 | G15: =IFERROR(E15/E14-1,"—") -> — | H15: ='🔧稼働率分析'!AK21 -> 0
A16: 📌 年間合計 | B16: =SUM(B4:B15) -> 208300 | C16: =SUM(C4:C15) -> 40800 | D16: =SUM(D4:D15) -> 172100 | E16: =SUM(E4:E15) -> 421200 | F16: =SUM(F4:F15) -> 353000 | H16: ='🔧稼働率分析'!AJ21 -> 0

Sheet 🔧稼働率分析
A1: 🔧 機器別 稼働率分析 第3期 2026年5月〜2027年4月
A2: 稼働率 = 実際の稼働回数 ÷ 1日最大稼働回数 × 日数 売上 ÷ 料金/回 = 稼働回数（推定）
A4: ⚙️ 前提条件（変更可）
A5: 機器タイプ | B5: 料金/回(円) | D5: 1回平均 利用時間(分) | F5: 取出し待ち(分) | H5: 1回あたり合計(分) | J5: 1日最大回転数 | L5: 備考 | N5: 営業日数
A6: M型 乾燥機(中) 10台 | B6: 300 | D6: 30 | F6: 20 | H6: =D6+F6 -> 50 | J6: =1440/H6 -> 28.8 | L6: 100円/10分 平均30分
A7: L型 乾燥機(大) 2台 | B7: 300 | D7: 24 | F7: 20 | H7: =D7+F7 -> 44 | J7: =1440/H7 -> 32.727273 | L7: 100円/8分 平均24分
A8: XL型 洗濯乾燥機 1台 | B8: 1150 | D8: 62 | F8: 20 | H8: =D8+F8 -> 82 | J8: =1440/H8 -> 17.560976 | L8: 平均1,150円 62分/回
A9: ※ 稼働率 ＝ 推定稼働回数 ÷（1日最大回転数 × 営業日数） 推定稼働回数 ＝ 月売上 ÷ 料金/回 黄色セルは変更可
A10: 📅 月別営業日数（黄色セルに入力） | B10: 31 | E10: 30 | H10: 31 | K10: 31 | N10: 30 | Q10: 31 | T10: 30 | W10: 31 | Z10: 31 | AC10: 28 | AF10: 31 | AI10: 30
A11: 機器名 | B11: 5月 | E11: 6月 | H11: 7月 | K11: 8月 | N11: 9月 | Q11: 10月 | T11: 11月 | W11: 12月 | Z11: 1月 | AC11: 2月 | AF11: 3月 | AI11: 4月 | AL11: 合計売上 | AM11: 合計回数 | AN11: 平均稼働率 | AO11: 評価
B12: 売上 | C12: 回数(推定) | D12: 稼働率 | E12: 売上 | F12: 回数(推定) | G12: 稼働率 | H12: 売上 | I12: 回数(推定) | J12: 稼働率 | K12: 売上 | L12: 回数(推定) | M12: 稼働率 | N12: 売上 | O12: 回数(推定) | P12: 稼働率 | Q12: 売上 | R12: 回数(推定) | S12: 稼働率 | T12: 売上 | U12: 回数(推定) | V12: 稼働率 | W12: 売上 | X12: 回数(推定) | Y12: 稼働率 | Z12: 売上 | AA12: 回数(推定) | AB12: 稼働率 | AC12: 売上 | AD12: 回数(推定) | AE12: 稼働率 | AF12: 売上 | AG12: 回数(推定) | AH12: 稼働率 | AI12: 売上 | AJ12: 回数(推定) | AK12: 稼働率
A13: 乾燥機(中) No.1&6 | B13: ='📊売上入力'!M5 -> 14600 | C13: =IFERROR(B13/B6,0) -> 48.666667 | D13: =IFERROR(C13/(J6*B10),0) -> 0.054510155 | E13: ='📊売上入力'!Y5 -> 1300 | F13: =IFERROR(E13/B6,0) -> 4.3333333 | G13: =IFERROR(F13/(J6*E10),0) -> 0.0050154321 | H13: ='📊売上入力'!AK5 -> 0 | I13: =IFERROR(H13/B6,0) -> 0 | J13: =IFERROR(I13/(J6*H10),0) -> 0 | K13: ='📊売上入力'!AW5 -> 0 | L13: =IFERROR(K13/B6,0) -> 0 | M13: =IFERROR(L13/(J6*K10),0) -> 0 | N13: ='📊売上入力'!BI5 -> 0 | O13: =IFERROR(N13/B6,0) -> 0 | P13: =IFERROR(O13/(J6*N10),0) -> 0 | Q13: ='📊売上入力'!BU5 -> 0 | R13: =IFERROR(Q13/B6,0) -> 0 | S13: =IFERROR(R13/(J6*Q10),0) -> 0 | T13: ='📊売上入力'!CG5 -> 0 | U13: =IFERROR(T13/B6,0) -> 0 | V13: =IFERROR(U13/(J6*T10),0) -> 0 | W13: ='📊売上入力'!CS5 -> 0 | X13: =IFERROR(W13/B6,0) -> 0 | Y13: =IFERROR(X13/(J6*W10),0) -> 0 | Z13: ='📊売上入力'!DE5 -> 0 | AA13: =IFERROR(Z13/B6,0) -> 0 | AB13: =IFERROR(AA13/(J6*Z10),0) -> 0 | AC13: ='📊売上入力'!DQ5 -> 0 | AD13: =IFERROR(AC13/B6,0) -> 0 | AE13: =IFERROR(AD13/(J6*AC10),0) -> 0 | AF13: ='📊売上入力'!EC5 -> 0 | AG13: =IFERROR(AF13/B6,0) -> 0 | AH13: =IFERROR(AG13/(J6*AF10),0) -> 0 | AI13: ='📊売上入力'!EO5 -> 0 | AJ13: =IFERROR(AI13/B6,0) -> 0 | AK13: =IFERROR(AJ13/(J6*AI10),0) -> 0 | AL13: =B13+E13+H13+K13+N13+Q13+T13+W13+Z13+AC13+AF13+AI13 -> 15900 | AM13: =C13+F13+I13+L13+O13+R13+U13+X13+AA13+AD13+AG13+AJ13 -> 53 | AN13: =IFERROR(AVERAGE(D13,G13,J13,M13,P13,S13,V13,Y13,AB13,AE13,AH13,AK13),0) -> 0.0049604656 | AO13: =IF(AH13>=0.7,"🟢 良好",IF(AH13>=0.4,"🟡 普通","🔴 要改善")) -> 🔴 要改善
A14: 乾燥機(中) No.2&7 | B14: ='📊売上入力'!M6 -> 30100 | C14: =IFERROR(B14/B6,0) -> 100.33333 | D14: =IFERROR(C14/(J6*B10),0) -> 0.11238053 | E14: ='📊売上入力'!Y6 -> 1600 | F14: =IFERROR(E14/B6,0) -> 5.3333333 | G14: =IFERROR(F14/(J6*E10),0) -> 0.0061728395 | H14: ='📊売上入力'!AK6 -> 0 | I14: =IFERROR(H14/B6,0) -> 0 | J14: =IFERROR(I14/(J6*H10),0) -> 0 | K14: ='📊売上入力'!AW6 -> 0 | L14: =IFERROR(K14/B6,0) -> 0 | M14: =IFERROR(L14/(J6*K10),0) -> 0 | N14: ='📊売上入力'!BI6 -> 0 | O14: =IFERROR(N14/B6,0) -> 0 | P14: =IFERROR(O14/(J6*N10),0) -> 0 | Q14: ='📊売上入力'!BU6 -> 0 | R14: =IFERROR(Q14/B6,0) -> 0 | S14: =IFERROR(R14/(J6*Q10),0) -> 0 | T14: ='📊売上入力'!CG6 -> 0 | U14: =IFERROR(T14/B6,0) -> 0 | V14: =IFERROR(U14/(J6*T10),0) -> 0 | W14: ='📊売上入力'!CS6 -> 0 | X14: =IFERROR(W14/B6,0) -> 0 | Y14: =IFERROR(X14/(J6*W10),0) -> 0 | Z14: ='📊売上入力'!DE6 -> 0 | AA14: =IFERROR(Z14/B6,0) -> 0 | AB14: =IFERROR(AA14/(J6*Z10),0) -> 0 | AC14: ='📊売上入力'!DQ6 -> 0 | AD14: =IFERROR(AC14/B6,0) -> 0 | AE14: =IFERROR(AD14/(J6*AC10),0) -> 0 | AF14: ='📊売上入力'!EC6 -> 0 | AG14: =IFERROR(AF14/B6,0) -> 0 | AH14: =IFERROR(AG14/(J6*AF10),0) -> 0 | AI14: ='📊売上入力'!EO6 -> 0 | AJ14: =IFERROR(AI14/B6,0) -> 0 | AK14: =IFERROR(AJ14/(J6*AI10),0) -> 0 | AL14: =B14+E14+H14+K14+N14+Q14+T14+W14+Z14+AC14+AF14+AI14 -> 31700 | AM14: =C14+F14+I14+L14+O14+R14+U14+X14+AA14+AD14+AG14+AJ14 -> 105.66667 | AN14: =IFERROR(AVERAGE(D14,G14,J14,M14,P14,S14,V14,Y14,AB14,AE14,AH14,AK14),0) -> 0.0098794471 | AO14: =IF(AH14>=0.7,"🟢 良好",IF(AH14>=0.4,"🟡 普通","🔴 要改善")) -> 🔴 要改善
A15: 乾燥機(中) No.3&8 | B15: ='📊売上入力'!M7 -> 41800 | C15: =IFERROR(B15/B6,0) -> 139.33333 | D15: =IFERROR(C15/(J6*B10),0) -> 0.15606332 | E15: ='📊売上入力'!Y7 -> 3100 | F15: =IFERROR(E15/B6,0) -> 10.333333 | G15: =IFERROR(F15/(J6*E10),0) -> 0.011959877 | H15: ='📊売上入力'!AK7 -> 0 | I15: =IFERROR(H15/B6,0) -> 0 | J15: =IFERROR(I15/(J6*H10),0) -> 0 | K15: ='📊売上入力'!AW7 -> 0 | L15: =IFERROR(K15/B6,0) -> 0 | M15: =IFERROR(L15/(J6*K10),0) -> 0 | N15: ='📊売上入力'!BI7 -> 0 | O15: =IFERROR(N15/B6,0) -> 0 | P15: =IFERROR(O15/(J6*N10),0) -> 0 | Q15: ='📊売上入力'!BU7 -> 0 | R15: =IFERROR(Q15/B6,0) -> 0 | S15: =IFERROR(R15/(J6*Q10),0) -> 0 | T15: ='📊売上入力'!CG7 -> 0 | U15: =IFERROR(T15/B6,0) -> 0 | V15: =IFERROR(U15/(J6*T10),0) -> 0 | W15: ='📊売上入力'!CS7 -> 0 | X15: =IFERROR(W15/B6,0) -> 0 | Y15: =IFERROR(X15/(J6*W10),0) -> 0 | Z15: ='📊売上入力'!DE7 -> 0 | AA15: =IFERROR(Z15/B6,0) -> 0 | AB15: =IFERROR(AA15/(J6*Z10),0) -> 0 | AC15: ='📊売上入力'!DQ7 -> 0 | AD15: =IFERROR(AC15/B6,0) -> 0 | AE15: =IFERROR(AD15/(J6*AC10),0) -> 0 | AF15: ='📊売上入力'!EC7 -> 0 | AG15: =IFERROR(AF15/B6,0) -> 0 | AH15: =IFERROR(AG15/(J6*AF10),0) -> 0 | AI15: ='📊売上入力'!EO7 -> 0 | AJ15: =IFERROR(AI15/B6,0) -> 0 | AK15: =IFERROR(AJ15/(J6*AI10),0) -> 0 | AL15: =B15+E15+H15+K15+N15+Q15+T15+W15+Z15+AC15+AF15+AI15 -> 44900 | AM15: =C15+F15+I15+L15+O15+R15+U15+X15+AA15+AD15+AG15+AJ15 -> 149.66667 | AN15: =IFERROR(AVERAGE(D15,G15,J15,M15,P15,S15,V15,Y15,AB15,AE15,AH15,AK15),0) -> 0.014001933 | AO15: =IF(AH15>=0.7,"🟢 良好",IF(AH15>=0.4,"🟡 普通","🔴 要改善")) -> 🔴 要改善
A16: 乾燥機(中) No.4&9 | B16: ='📊売上入力'!M8 -> 55700 | C16: =IFERROR(B16/B6,0) -> 185.66667 | D16: =IFERROR(C16/(J6*B10),0) -> 0.20795998 | E16: ='📊売上入力'!Y8 -> 4900 | F16: =IFERROR(E16/B6,0) -> 16.333333 | G16: =IFERROR(F16/(J6*E10),0) -> 0.018904321 | H16: ='📊売上入力'!AK8 -> 0 | I16: =IFERROR(H16/B6,0) -> 0 | J16: =IFERROR(I16/(J6*H10),0) -> 0 | K16: ='📊売上入力'!AW8 -> 0 | L16: =IFERROR(K16/B6,0) -> 0 | M16: =IFERROR(L16/(J6*K10),0) -> 0 | N16: ='📊売上入力'!BI8 -> 0 | O16: =IFERROR(N16/B6,0) -> 0 | P16: =IFERROR(O16/(J6*N10),0) -> 0 | Q16: ='📊売上入力'!BU8 -> 0 | R16: =IFERROR(Q16/B6,0) -> 0 | S16: =IFERROR(R16/(J6*Q10),0) -> 0 | T16: ='📊売上入力'!CG8 -> 0 | U16: =IFERROR(T16/B6,0) -> 0 | V16: =IFERROR(U16/(J6*T10),0) -> 0 | W16: ='📊売上入力'!CS8 -> 0 | X16: =IFERROR(W16/B6,0) -> 0 | Y16: =IFERROR(X16/(J6*W10),0) -> 0 | Z16: ='📊売上入力'!DE8 -> 0 | AA16: =IFERROR(Z16/B6,0) -> 0 | AB16: =IFERROR(AA16/(J6*Z10),0) -> 0 | AC16: ='📊売上入力'!DQ8 -> 0 | AD16: =IFERROR(AC16/B6,0) -> 0 | AE16: =IFERROR(AD16/(J6*AC10),0) -> 0 | AF16: ='📊売上入力'!EC8 -> 0 | AG16: =IFERROR(AF16/B6,0) -> 0 | AH16: =IFERROR(AG16/(J6*AF10),0) -> 0 | AI16: ='📊売上入力'!EO8 -> 0 | AJ16: =IFERROR(AI16/B6,0) -> 0 | AK16: =IFERROR(AJ16/(J6*AI10),0) -> 0 | AL16: =B16+E16+H16+K16+N16+Q16+T16+W16+Z16+AC16+AF16+AI16 -> 60600 | AM16: =C16+F16+I16+L16+O16+R16+U16+X16+AA16+AD16+AG16+AJ16 -> 202 | AN16: =IFERROR(AVERAGE(D16,G16,J16,M16,P16,S16,V16,Y16,AB16,AE16,AH16,AK16),0) -> 0.018905358 | AO16: =IF(AH16>=0.7,"🟢 良好",IF(AH16>=0.4,"🟡 普通","🔴 要改善")) -> 🔴 要改善
A17: 乾燥機(中) No.5&10 | B17: ='📊売上入力'!M9 -> 49700 | C17: =IFERROR(B17/B6,0) -> 165.66667 | D17: =IFERROR(C17/(J6*B10),0) -> 0.18555854 | E17: ='📊売上入力'!Y9 -> 5500 | F17: =IFERROR(E17/B6,0) -> 18.333333 | G17: =IFERROR(F17/(J6*E10),0) -> 0.021219136 | H17: ='📊売上入力'!AK9 -> 0 | I17: =IFERROR(H17/B6,0) -> 0 | J17: =IFERROR(I17/(J6*H10),0) -> 0 | K17: ='📊売上入力'!AW9 -> 0 | L17: =IFERROR(K17/B6,0) -> 0 | M17: =IFERROR(L17/(J6*K10),0) -> 0 | N17: ='📊売上入力'!BI9 -> 0 | O17: =IFERROR(N17/B6,0) -> 0 | P17: =IFERROR(O17/(J6*N10),0) -> 0 | Q17: ='📊売上入力'!BU9 -> 0 | R17: =IFERROR(Q17/B6,0) -> 0 | S17: =IFERROR(R17/(J6*Q10),0) -> 0 | T17: ='📊売上入力'!CG9 -> 0 | U17: =IFERROR(T17/B6,0) -> 0 | V17: =IFERROR(U17/(J6*T10),0) -> 0 | W17: ='📊売上入力'!CS9 -> 0 | X17: =IFERROR(W17/B6,0) -> 0 | Y17: =IFERROR(X17/(J6*W10),0) -> 0 | Z17: ='📊売上入力'!DE9 -> 0 | AA17: =IFERROR(Z17/B6,0) -> 0 | AB17: =IFERROR(AA17/(J6*Z10),0) -> 0 | AC17: ='📊売上入力'!DQ9 -> 0 | AD17: =IFERROR(AC17/B6,0) -> 0 | AE17: =IFERROR(AD17/(J6*AC10),0) -> 0 | AF17: ='📊売上入力'!EC9 -> 0 | AG17: =IFERROR(AF17/B6,0) -> 0 | AH17: =IFERROR(AG17/(J6*AF10),0) -> 0 | AI17: ='📊売上入力'!EO9 -> 0 | AJ17: =IFERROR(AI17/B6,0) -> 0 | AK17: =IFERROR(AJ17/(J6*AI10),0) -> 0 | AL17: =B17+E17+H17+K17+N17+Q17+T17+W17+Z17+AC17+AF17+AI17 -> 55200 | AM17: =C17+F17+I17+L17+O17+R17+U17+X17+AA17+AD17+AG17+AJ17 -> 184 | AN17: =IFERROR(AVERAGE(D17,G17,J17,M17,P17,S17,V17,Y17,AB17,AE17,AH17,AK17),0) -> 0.017231473 | AO17: =IF(AH17>=0.7,"🟢 良好",IF(AH17>=0.4,"🟡 普通","🔴 要改善")) -> 🔴 要改善
A18: 乾燥機(大) No.1 | B18: ='📊売上入力'!M10 -> 25400 | C18: =IFERROR(B18/B7,0) -> 84.666667 | D18: =IFERROR(C18/(J7*B10),0) -> 0.083452808 | E18: ='📊売上入力'!Y10 -> 3300 | F18: =IFERROR(E18/B7,0) -> 11 | G18: =IFERROR(F18/(J7*E10),0) -> 0.011203704 | H18: ='📊売上入力'!AK10 -> 0 | I18: =IFERROR(H18/B7,0) -> 0 | J18: =IFERROR(I18/(J7*H10),0) -> 0 | K18: ='📊売上入力'!AW10 -> 0 | L18: =IFERROR(K18/B7,0) -> 0 | M18: =IFERROR(L18/(J7*K10),0) -> 0 | N18: ='📊売上入力'!BI10 -> 0 | O18: =IFERROR(N18/B7,0) -> 0 | P18: =IFERROR(O18/(J7*N10),0) -> 0 | Q18: ='📊売上入力'!BU10 -> 0 | R18: =IFERROR(Q18/B7,0) -> 0 | S18: =IFERROR(R18/(J7*Q10),0) -> 0 | T18: ='📊売上入力'!CG10 -> 0 | U18: =IFERROR(T18/B7,0) -> 0 | V18: =IFERROR(U18/(J7*T10),0) -> 0 | W18: ='📊売上入力'!CS10 -> 0 | X18: =IFERROR(W18/B7,0) -> 0 | Y18: =IFERROR(X18/(J7*W10),0) -> 0 | Z18: ='📊売上入力'!DE10 -> 0 | AA18: =IFERROR(Z18/B7,0) -> 0 | AB18: =IFERROR(AA18/(J7*Z10),0) -> 0 | AC18: ='📊売上入力'!DQ10 -> 0 | AD18: =IFERROR(AC18/B7,0) -> 0 | AE18: =IFERROR(AD18/(J7*AC10),0) -> 0 | AF18: ='📊売上入力'!EC10 -> 0 | AG18: =IFERROR(AF18/B7,0) -> 0 | AH18: =IFERROR(AG18/(J7*AF10),0) -> 0 | AI18: ='📊売上入力'!EO10 -> 0 | AJ18: =IFERROR(AI18/B7,0) -> 0 | AK18: =IFERROR(AJ18/(J7*AI10),0) -> 0 | AL18: =B18+E18+H18+K18+N18+Q18+T18+W18+Z18+AC18+AF18+AI18 -> 28700 | AM18: =C18+F18+I18+L18+O18+R18+U18+X18+AA18+AD18+AG18+AJ18 -> 95.666667 | AN18: =IFERROR(AVERAGE(D18,G18,J18,M18,P18,S18,V18,Y18,AB18,AE18,AH18,AK18),0) -> 0.0078880426 | AO18: =IF(AH18>=0.7,"🟢 良好",IF(AH18>=0.4,"🟡 普通","🔴 要改善")) -> 🔴 要改善
A19: 乾燥機(大) No.2 | B19: ='📊売上入力'!M11 -> 10400 | C19: =IFERROR(B19/B7,0) -> 34.666667 | D19: =IFERROR(C19/(J7*B10),0) -> 0.034169654 | E19: ='📊売上入力'!Y11 -> 1700 | F19: =IFERROR(E19/B7,0) -> 5.6666667 | G19: =IFERROR(F19/(J7*E10),0) -> 0.0057716049 | H19: ='📊売上入力'!AK11 -> 0 | I19: =IFERROR(H19/B7,0) -> 0 | J19: =IFERROR(I19/(J7*H10),0) -> 0 | K19: ='📊売上入力'!AW11 -> 0 | L19: =IFERROR(K19/B7,0) -> 0 | M19: =IFERROR(L19/(J7*K10),0) -> 0 | N19: ='📊売上入力'!BI11 -> 0 | O19: =IFERROR(N19/B7,0) -> 0 | P19: =IFERROR(O19/(J7*N10),0) -> 0 | Q19: ='📊売上入力'!BU11 -> 0 | R19: =IFERROR(Q19/B7,0) -> 0 | S19: =IFERROR(R19/(J7*Q10),0) -> 0 | T19: ='📊売上入力'!CG11 -> 0 | U19: =IFERROR(T19/B7,0) -> 0 | V19: =IFERROR(U19/(J7*T10),0) -> 0 | W19: ='📊売上入力'!CS11 -> 0 | X19: =IFERROR(W19/B7,0) -> 0 | Y19: =IFERROR(X19/(J7*W10),0) -> 0 | Z19: ='📊売上入力'!DE11 -> 0 | AA19: =IFERROR(Z19/B7,0) -> 0 | AB19: =IFERROR(AA19/(J7*Z10),0) -> 0 | AC19: ='📊売上入力'!DQ11 -> 0 | AD19: =IFERROR(AC19/B7,0) -> 0 | AE19: =IFERROR(AD19/(J7*AC10),0) -> 0 | AF19: ='📊売上入力'!EC11 -> 0 | AG19: =IFERROR(AF19/B7,0) -> 0 | AH19: =IFERROR(AG19/(J7*AF10),0) -> 0 | AI19: ='📊売上入力'!EO11 -> 0 | AJ19: =IFERROR(AI19/B7,0) -> 0 | AK19: =IFERROR(AJ19/(J7*AI10),0) -> 0 | AL19: =B19+E19+H19+K19+N19+Q19+T19+W19+Z19+AC19+AF19+AI19 -> 12100 | AM19: =C19+F19+I19+L19+O19+R19+U19+X19+AA19+AD19+AG19+AJ19 -> 40.333333 | AN19: =IFERROR(AVERAGE(D19,G19,J19,M19,P19,S19,V19,Y19,AB19,AE19,AH19,AK19),0) -> 0.0033284382 | AO19: =IF(AH19>=0.7,"🟢 良好",IF(AH19>=0.4,"🟡 普通","🔴 要改善")) -> 🔴 要改善
A20: 洗濯乾燥機 No.1 | B20: ='📊売上入力'!M12 -> 152800 | C20: =IFERROR(B20/B8,0) -> 132.86957 | D20: =IFERROR(C20/(J8*B10),0) -> 0.24407044 | E20: ='📊売上入力'!Y12 -> 19300 | F20: =IFERROR(E20/B8,0) -> 16.782609 | G20: =IFERROR(F20/(J8*E10),0) -> 0.031855878 | H20: ='📊売上入力'!AK12 -> 0 | I20: =IFERROR(H20/B8,0) -> 0 | J20: =IFERROR(I20/(J8*H10),0) -> 0 | K20: ='📊売上入力'!AW12 -> 0 | L20: =IFERROR(K20/B8,0) -> 0 | M20: =IFERROR(L20/(J8*K10),0) -> 0 | N20: ='📊売上入力'!BI12 -> 0 | O20: =IFERROR(N20/B8,0) -> 0 | P20: =IFERROR(O20/(J8*N10),0) -> 0 | Q20: ='📊売上入力'!BU12 -> 0 | R20: =IFERROR(Q20/B8,0) -> 0 | S20: =IFERROR(R20/(J8*Q10),0) -> 0 | T20: ='📊売上入力'!CG12 -> 0 | U20: =IFERROR(T20/B8,0) -> 0 | V20: =IFERROR(U20/(J8*T10),0) -> 0 | W20: ='📊売上入力'!CS12 -> 0 | X20: =IFERROR(W20/B8,0) -> 0 | Y20: =IFERROR(X20/(J8*W10),0) -> 0 | Z20: ='📊売上入力'!DE12 -> 0 | AA20: =IFERROR(Z20/B8,0) -> 0 | AB20: =IFERROR(AA20/(J8*Z10),0) -> 0 | AC20: ='📊売上入力'!DQ12 -> 0 | AD20: =IFERROR(AC20/B8,0) -> 0 | AE20: =IFERROR(AD20/(J8*AC10),0) -> 0 | AF20: ='📊売上入力'!EC12 -> 0 | AG20: =IFERROR(AF20/B8,0) -> 0 | AH20: =IFERROR(AG20/(J8*AF10),0) -> 0 | AI20: ='📊売上入力'!EO12 -> 0 | AJ20: =IFERROR(AI20/B8,0) -> 0 | AK20: =IFERROR(AJ20/(J8*AI10),0) -> 0 | AL20: =B20+E20+H20+K20+N20+Q20+T20+W20+Z20+AC20+AF20+AI20 -> 172100 | AM20: =C20+F20+I20+L20+O20+R20+U20+X20+AA20+AD20+AG20+AJ20 -> 149.65217 | AN20: =IFERROR(AVERAGE(D20,G20,J20,M20,P20,S20,V20,Y20,AB20,AE20,AH20,AK20),0) -> 0.02299386 | AO20: =IF(AH20>=0.7,"🟢 良好",IF(AH20>=0.4,"🟡 普通","🔴 要改善")) -> 🔴 要改善
A21: 📌 全機器合計 | B21: =SUM(B13:B20) -> 380500 | C21: =SUM(C13:C20) -> 891.86957 | D21: =IFERROR(AVERAGE(D13:D20),0) -> 0.13477068 | E21: =SUM(E13:E20) -> 40700 | F21: =SUM(F13:F20) -> 88.115942 | G21: =IFERROR(AVERAGE(G13:G20),0) -> 0.014012849 | H21: =SUM(H13:H20) -> 0 | I21: =SUM(I13:I20) -> 0 | J21: =IFERROR(AVERAGE(J13:J20),0) -> 0 | K21: =SUM(K13:K20) -> 0 | L21: =SUM(L13:L20) -> 0 | M21: =IFERROR(AVERAGE(M13:M20),0) -> 0 | N21: =SUM(N13:N20) -> 0 | O21: =SUM(O13:O20) -> 0 | P21: =IFERROR(AVERAGE(P13:P20),0) -> 0 | Q21: =SUM(Q13:Q20) -> 0 | R21: =SUM(R13:R20) -> 0 | S21: =IFERROR(AVERAGE(S13:S20),0) -> 0 | T21: =SUM(T13:T20) -> 0 | U21: =SUM(U13:U20) -> 0 | V21: =IFERROR(AVERAGE(V13:V20),0) -> 0 | W21: =SUM(W13:W20) -> 0 | X21: =SUM(X13:X20) -> 0 | Y21: =IFERROR(AVERAGE(Y13:Y20),0) -> 0 | Z21: =SUM(Z13:Z20) -> 0 | AA21: =SUM(AA13:AA20) -> 0 | AB21: =IFERROR(AVERAGE(AB13:AB20),0) -> 0 | AC21: =SUM(AC13:AC20) -> 0 | AD21: =SUM(AD13:AD20) -> 0 | AE21: =IFERROR(AVERAGE(AE13:AE20),0) -> 0 | AF21: =SUM(AF13:AF20) -> 0 | AG21: =SUM(AG13:AG20) -> 0 | AH21: =IFERROR(AVERAGE(AH13:AH20),0) -> 0 | AI21: =SUM(AI13:AI20) -> 0 | AJ21: =SUM(AJ13:AJ20) -> 0 | AK21: =IFERROR(AVERAGE(AK13:AK20),0) -> 0 | AL21: =SUM(AL13:AL20) -> 421200 | AM21: =SUM(AM13:AM20) -> 979.98551 | AN21: =IFERROR(AVERAGE(AH13:AH20),0) -> 0
A22: 🟢 良好：稼働率 70%以上
A23: 🟡 普通：稼働率 40〜70%
A24: 🔴 要改善：稼働率 40%未満

Sheet 💰経費・人件費
A1: 💰 月次 経費・人件費 管理 第3期 2026年5月〜2027年4月
A3: 🔌 月次 固定費（光熱費・通信費）
A4: 項目 | B4: 46143 | C4: 46174 | D4: 46204 | E4: 46235 | F4: 46266 | G4: 46296 | H4: 46327 | I4: 46357 | J4: 46388 | K4: 46419 | L4: 46447 | M4: 46478 | N4: 合計
A5: ガス | N5: =SUM(B5:M5) -> 0
A6: 電気 | N6: =SUM(B6:M6) -> 0
A7: 水道 | N7: =SUM(B7:M7) -> 0
A8: WiFi・通信費 | N8: =SUM(B8:M8) -> 0
A9: その他経費（消耗品など） | N9: =SUM(B9:M9) -> 0
A10: 📌 月計 | B10: =SUM(B5:B9) -> 0 | C10: =SUM(C5:C9) -> 0 | D10: =SUM(D5:D9) -> 0 | E10: =SUM(E5:E9) -> 0 | F10: =SUM(F5:F9) -> 0 | G10: =SUM(G5:G9) -> 0 | H10: =SUM(H5:H9) -> 0 | I10: =SUM(I5:I9) -> 0 | ... N10: =SUM(N5:N9) -> 0
A12: 🔌 月次 固定費（光熱費・通信費）
A13: 項目 | B13: 46143 | C13: 46174 | D13: 46204 | E13: 46235 | F13: 46266 | G13: 46296 | H13: 46327 | I13: 46357 | J13: 46388 | K13: 46419 | L13: 46447 | M13: 46478 | N13: 年計
A14: 下里清代 | B14: =SUMIFS($G$24:$G$93, $B$24:$B$93, $A14, $A$24:$A$93, ">="&B$13, $A$24:$A$93, "<="&EOMONTH(B$13, 0)) -> 22898.333 | C14: =SUMIFS($G$24:$G$93, $B$24:$B$93, $A14, $A$24:$A$93, ">="&C$13, $A$24:$A$93, "<="&EOMONTH(C$13, 0)) -> 4821.6667 | D14: =SUMIFS($G$24:$G$93, $B$24:$B$93, $A14, $A$24:$A$93, ">="&D$13, $A$24:$A$93, "<="&EOMONTH(D$13, 0)) -> 0 | E14: =SUMIFS($G$24:$G$93, $B$24:$B$93, $A14, $A$24:$A$93, ">="&E$13, $A$24:$A$93, "<="&EOMONTH(E$13, 0)) -> 0 | F14: =SUMIFS($G$24:$G$93, $B$24:$B$93, $A14, $A$24:$A$93, ">="&F$13, $A$24:$A$93, "<="&EOMONTH(F$13, 0)) -> 0 | G14: =SUMIFS($G$24:$G$93, $B$24:$B$93, $A14, $A$24:$A$93, ">="&G$13, $A$24:$A$93, "<="&EOMONTH(G$13, 0)) -> 0 | H14: =SUMIFS($G$24:$G$93, $B$24:$B$93, $A14, $A$24:$A$93, ">="&H$13, $A$24:$A$93, "<="&EOMONTH(H$13, 0)) -> 0 | I14: =SUMIFS($G$24:$G$93, $B$24:$B$93, $A14, $A$24:$A$93, ">="&I$13, $A$24:$A$93, "<="&EOMONTH(I$13, 0)) -> 0 | ... M14: =SUMIFS($G$24:$G$93, $B$24:$B$93, $A14, $A$24:$A$93, ">="&M$13, $A$24:$A$93, "<="&EOMONTH(M$13, 0)) -> 0 | N14: =SUM(B14:M14) -> 27720
B15: =SUMIFS($E$24:$E$93, $B$24:$B$93, $A14, $A$24:$A$93, ">="&B$13, $A$24:$A$93, "<="&EOMONTH(B$13, 0)) -> 0.86736111 | C15: =SUMIFS($E$24:$E$93, $B$24:$B$93, $A14, $A$24:$A$93, ">="&C$13, $A$24:$A$93, "<="&EOMONTH(C$13, 0)) -> 0.18263889 | D15: =SUMIFS($E$24:$E$93, $B$24:$B$93, $A14, $A$24:$A$93, ">="&D$13, $A$24:$A$93, "<="&EOMONTH(D$13, 0)) -> 0 | E15: =SUMIFS($E$24:$E$93, $B$24:$B$93, $A14, $A$24:$A$93, ">="&E$13, $A$24:$A$93, "<="&EOMONTH(E$13, 0)) -> 0 | F15: =SUMIFS($E$24:$E$93, $B$24:$B$93, $A14, $A$24:$A$93, ">="&F$13, $A$24:$A$93, "<="&EOMONTH(F$13, 0)) -> 0 | G15: =SUMIFS($E$24:$E$93, $B$24:$B$93, $A14, $A$24:$A$93, ">="&G$13, $A$24:$A$93, "<="&EOMONTH(G$13, 0)) -> 0 | H15: =SUMIFS($E$24:$E$93, $B$24:$B$93, $A14, $A$24:$A$93, ">="&H$13, $A$24:$A$93, "<="&EOMONTH(H$13, 0)) -> 0 | I15: =SUMIFS($E$24:$E$93, $B$24:$B$93, $A14, $A$24:$A$93, ">="&I$13, $A$24:$A$93, "<="&EOMONTH(I$13, 0)) -> 0 | ... M15: =SUMIFS($E$24:$E$93, $B$24:$B$93, $A14, $A$24:$A$93, ">="&M$13, $A$24:$A$93, "<="&EOMONTH(M$13, 0)) -> 0 | N15: =SUM(B15:M15) -> 1.05
A16: 岡村 | B16: =SUMIFS($G$24:$G$93, $B$24:$B$93, $A16, $A$24:$A$93, ">="&B$13, $A$24:$A$93, "<="&EOMONTH(B$13, 0)) -> 0 | C16: =SUMIFS($G$24:$G$93, $B$24:$B$93, $A16, $A$24:$A$93, ">="&C$13, $A$24:$A$93, "<="&EOMONTH(C$13, 0)) -> 0 | D16: =SUMIFS($G$24:$G$93, $B$24:$B$93, $A16, $A$24:$A$93, ">="&D$13, $A$24:$A$93, "<="&EOMONTH(D$13, 0)) -> 0 | E16: =SUMIFS($G$24:$G$93, $B$24:$B$93, $A16, $A$24:$A$93, ">="&E$13, $A$24:$A$93, "<="&EOMONTH(E$13, 0)) -> 0 | F16: =SUMIFS($G$24:$G$93, $B$24:$B$93, $A16, $A$24:$A$93, ">="&F$13, $A$24:$A$93, "<="&EOMONTH(F$13, 0)) -> 0 | G16: =SUMIFS($G$24:$G$93, $B$24:$B$93, $A16, $A$24:$A$93, ">="&G$13, $A$24:$A$93, "<="&EOMONTH(G$13, 0)) -> 0 | H16: =SUMIFS($G$24:$G$93, $B$24:$B$93, $A16, $A$24:$A$93, ">="&H$13, $A$24:$A$93, "<="&EOMONTH(H$13, 0)) -> 0 | I16: =SUMIFS($G$24:$G$93, $B$24:$B$93, $A16, $A$24:$A$93, ">="&I$13, $A$24:$A$93, "<="&EOMONTH(I$13, 0)) -> 0 | ... M16: =SUMIFS($G$24:$G$93, $B$24:$B$93, $A16, $A$24:$A$93, ">="&M$13, $A$24:$A$93, "<="&EOMONTH(M$13, 0)) -> 0 | N16: =SUM(B16:M16) -> 0
B17: =SUMIFS($E$24:$E$93, $B$24:$B$93, $A16, $A$24:$A$93, ">="&B$13, $A$24:$A$93, "<="&EOMONTH(B$13, 0)) -> 0.25 | C17: =SUMIFS($E$24:$E$93, $B$24:$B$93, $A16, $A$24:$A$93, ">="&C$13, $A$24:$A$93, "<="&EOMONTH(C$13, 0)) -> 0.0625 | D17: =SUMIFS($E$24:$E$93, $B$24:$B$93, $A16, $A$24:$A$93, ">="&D$13, $A$24:$A$93, "<="&EOMONTH(D$13, 0)) -> 0 | E17: =SUMIFS($E$24:$E$93, $B$24:$B$93, $A16, $A$24:$A$93, ">="&E$13, $A$24:$A$93, "<="&EOMONTH(E$13, 0)) -> 0 | F17: =SUMIFS($E$24:$E$93, $B$24:$B$93, $A16, $A$24:$A$93, ">="&F$13, $A$24:$A$93, "<="&EOMONTH(F$13, 0)) -> 0 | G17: =SUMIFS($E$24:$E$93, $B$24:$B$93, $A16, $A$24:$A$93, ">="&G$13, $A$24:$A$93, "<="&EOMONTH(G$13, 0)) -> 0 | H17: =SUMIFS($E$24:$E$93, $B$24:$B$93, $A16, $A$24:$A$93, ">="&H$13, $A$24:$A$93, "<="&EOMONTH(H$13, 0)) -> 0 | I17: =SUMIFS($E$24:$E$93, $B$24:$B$93, $A16, $A$24:$A$93, ">="&I$13, $A$24:$A$93, "<="&EOMONTH(I$13, 0)) -> 0 | ... M17: =SUMIFS($E$24:$E$93, $B$24:$B$93, $A16, $A$24:$A$93, ">="&M$13, $A$24:$A$93, "<="&EOMONTH(M$13, 0)) -> 0 | N17: =SUM(B17:M17) -> 0.3125
N18: =SUM(B18:M18) -> 0
N19: =SUM(B19:M19) -> 0
A20: 📌 月計 | B20: =SUM(B14:B19) -> 22899.451 | C20: =SUM(C14:C19) -> 4821.9118 | D20: =SUM(D14:D19) -> 0 | E20: =SUM(E14:E19) -> 0 | F20: =SUM(F14:F19) -> 0 | G20: =SUM(G14:G19) -> 0 | H20: =SUM(H14:H19) -> 0 | I20: =SUM(I14:I19) -> 0 | ... M20: =SUM(M14:M19) -> 0 | N20: =SUM(B20:C20) -> 27721.362
A22: 👷 清掃 人件費記録（バイト時給 ¥1,100 / 岡村 無給）
A23: 日付 | B23: 担当者 | C23: 開始 | D23: 終了 | E23: 時間(h) | F23: 時給 | G23: 人件費 | H23: メモ
A24: 46143 | B24: 下里清代 | C24: 0.41666667 | D24: 0.5 | E24: =IFERROR(TIMEVALUE(D24)-TIMEVALUE(C24), 0) -> 0.083333333 | F24: =IF(B24="岡村",0,IF(B24<>"",1100,0)) -> 1100 | G24: =E24*24*F24 -> 2200
A25: 46146 | B25: 下里清代 | C25: 0.48263889 | D25: 0.58333333 | E25: =IFERROR(TIMEVALUE(D25)-TIMEVALUE(C25), 0) -> 0.10069444 | F25: =IF(B25="岡村",0,IF(B25<>"",1100,0)) -> 1100 | G25: =E25*24*F25 -> 2658.3333
A26: 46149 | B26: 岡村 | C26: 0.625 | D26: 0.6875 | E26: =IFERROR(TIMEVALUE(D26)-TIMEVALUE(C26), 0) -> 0.0625 | F26: =IF(B26="岡村",0,IF(B26<>"",1100,0)) -> 0 | G26: =E26*24*F26 -> 0
A27: 46150 | B27: 下里清代 | C27: 0.58333333 | D27: 0.67708333 | E27: =IFERROR(TIMEVALUE(D27)-TIMEVALUE(C27), 0) -> 0.09375 | F27: =IF(B27="岡村",0,IF(B27<>"",1100,0)) -> 1100 | G27: =E27*24*F27 -> 2475
A28: 46153 | B28: 下里清代 | C28: 0.60486111 | D28: 0.68611111 | E28: =IFERROR(TIMEVALUE(D28)-TIMEVALUE(C28), 0) -> 0.08125 | F28: =IF(B28="岡村",0,IF(B28<>"",1100,0)) -> 1100 | G28: =E28*24*F28 -> 2145
A29: 46155 | B29: 岡村 | C29: 0.625 | D29: 0.6875 | E29: =IFERROR(TIMEVALUE(D29)-TIMEVALUE(C29), 0) -> 0.0625 | F29: =IF(B29="岡村",0,IF(B29<>"",1100,0)) -> 0 | G29: =E29*24*F29 -> 0
A30: 46157 | B30: 下里清代 | C30: 0.41319444 | D30: 0.5 | E30: =IFERROR(TIMEVALUE(D30)-TIMEVALUE(C30), 0) -> 0.086805556 | F30: =IF(B30="岡村",0,IF(B30<>"",1100,0)) -> 1100 | G30: =E30*24*F30 -> 2291.6667
A31: 46160 | B31: 下里清代 | C31: 0.41319444 | D31: 0.5 | E31: =IFERROR(TIMEVALUE(D31)-TIMEVALUE(C31), 0) -> 0.086805556 | F31: =IF(B31="岡村",0,IF(B31<>"",1100,0)) -> 1100 | G31: =E31*24*F31 -> 2291.6667
A32: 46163 | B32: 下里清代 | C32: 0.41319444 | D32: 0.49930556 | E32: =IFERROR(TIMEVALUE(D32)-TIMEVALUE(C32), 0) -> 0.086111111 | F32: =IF(B32="岡村",0,IF(B32<>"",1100,0)) -> 1100 | G32: =E32*24*F32 -> 2273.3333
A33: 46164 | B33: 岡村 | C33: 0.625 | D33: 0.6875 | E33: =IFERROR(TIMEVALUE(D33)-TIMEVALUE(C33), 0) -> 0.0625 | F33: =IF(B33="岡村",0,IF(B33<>"",1100,0)) -> 0 | G33: =E33*24*F33 -> 0
A34: 46167 | B34: 下里清代 | C34: 0.60416667 | D34: 0.69166667 | E34: =IFERROR(TIMEVALUE(D34)-TIMEVALUE(C34), 0) -> 0.0875 | F34: =IF(B34="岡村",0,IF(B34<>"",1100,0)) -> 1100 | G34: =E34*24*F34 -> 2310
A35: 46169 | B35: 岡村 | C35: 0.625 | D35: 0.6875 | E35: =IFERROR(TIMEVALUE(D35)-TIMEVALUE(C35), 0) -> 0.0625 | F35: =IF(B35="岡村",0,IF(B35<>"",1100,0)) -> 0 | G35: =E35*24*F35 -> 0
... A40: 46178 | B40: 下里清代 | C40: 0.33194444 | D40: 0.42222222 | E40: =IFERROR(TIMEVALUE(D40)-TIMEVALUE(C40), 0) -> 0.090277778 | F40: =IF(B40="岡村",0,IF(B40<>"",1100,0)) -> 1100 | G40: =E40*24*F40 -> 2383.3333
E41: =IFERROR(TIMEVALUE(D41)-TIMEVALUE(C41), 0) -> 0 | F41: =IF(B41="岡村",0,IF(B41<>"",1100,0)) -> 0 | G41: =E41*24*F41 -> 0
E42: =IFERROR(TIMEVALUE(D42)-TIMEVALUE(C42), 0) -> 0 | F42: =IF(B42="岡村",0,IF(B42<>"",1100,0)) -> 0 | G42: =E42*24*F42 -> 0
E43: =IFERROR(TIMEVALUE(D43)-TIMEVALUE(C43), 0) -> 0 | F43: =IF(B43="岡村",0,IF(B43<>"",1100,0)) -> 0 | G43: =E43*24*F43 -> 0
E44: =IFERROR(TIMEVALUE(D44)-TIMEVALUE(C44), 0) -> 0 | F44: =IF(B44="岡村",0,IF(B44<>"",1100,0)) -> 0 | G44: =E44*24*F44 -> 0
E45: =IFERROR(TIMEVALUE(D45)-TIMEVALUE(C45), 0) -> 0 | F45: =IF(B45="岡村",0,IF(B45<>"",1100,0)) -> 0 | G45: =E45*24*F45 -> 0
E46: =IFERROR(TIMEVALUE(D46)-TIMEVALUE(C46), 0) -> 0 | F46: =IF(B46="岡村",0,IF(B46<>"",1100,0)) -> 0 | G46: =E46*24*F46 -> 0
E47: =IFERROR(TIMEVALUE(D47)-TIMEVALUE(C47), 0) -> 0 | F47: =IF(B47="岡村",0,IF(B47<>"",1100,0)) -> 0 | G47: =E47*24*F47 -> 0
...

Sheet 📋損益サマリー
B1: 📋 月次 損益サマリー（P&L） 第3期 2027年5月〜2028年4月
B3: 項目 | C3: 46143 | D3: 46174 | E3: 46204 | F3: 46235 | G3: 46266 | H3: 46296 | I3: 46327 | J3: 46357 | K3: 46388 | L3: 46419 | M3: 46447 | N3: 46478 | O3: 年計 | P3: 月平均
B4: 売上合計 | C4: ='📈月次サマリー'!E4 -> 380500 | D4: ='📈月次サマリー'!E5 -> 40700 | E4: ='📈月次サマリー'!E6 -> 0 | F4: ='📈月次サマリー'!E7 -> 0 | G4: ='📈月次サマリー'!E8 -> 0 | H4: ='📈月次サマリー'!E9 -> 0 | I4: ='📈月次サマリー'!E10 -> 0 | J4: ='📈月次サマリー'!E11 -> 0 | K4: ='📈月次サマリー'!E12 -> 0 | L4: ='📈月次サマリー'!E13 -> 0 | M4: ='📈月次サマリー'!E14 -> 0 | N4: ='📈月次サマリー'!E15 -> 0 | O4: =SUM(C4:N4) -> 421200 | P4: =IFERROR(O4/COUNTIF(C4:N4,"<>0"),0) -> 210600
B5: ガス | C5: ='💰経費・人件費'!B5 | D5: ='💰経費・人件費'!C5 | E5: ='💰経費・人件費'!D5 | F5: ='💰経費・人件費'!E5 | G5: ='💰経費・人件費'!F5 | H5: ='💰経費・人件費'!G5 | I5: ='💰経費・人件費'!H5 | J5: ='💰経費・人件費'!I5 | ... N5: ='💰経費・人件費'!M5 | O5: =SUM(C5:N5) -> 0 | P5: =IFERROR(O5/COUNTIF(C5:N5,"<>0"),0) -> 0
B6: 電気 | C6: ='💰経費・人件費'!B6 | D6: ='💰経費・人件費'!C6 | E6: ='💰経費・人件費'!D6 | F6: ='💰経費・人件費'!E6 | G6: ='💰経費・人件費'!F6 | H6: ='💰経費・人件費'!G6 | I6: ='💰経費・人件費'!H6 | J6: ='💰経費・人件費'!I6 | ... N6: ='💰経費・人件費'!M6 | O6: =SUM(C6:N6) -> 0 | P6: =IFERROR(O6/COUNTIF(C6:N6,"<>0"),0) -> 0
B7: 水道 | C7: ='💰経費・人件費'!B7 | D7: ='💰経費・人件費'!C7 | E7: ='💰経費・人件費'!D7 | F7: ='💰経費・人件費'!E7 | G7: ='💰経費・人件費'!F7 | H7: ='💰経費・人件費'!G7 | I7: ='💰経費・人件費'!H7 | J7: ='💰経費・人件費'!I7 | ... N7: ='💰経費・人件費'!M7 | O7: =SUM(C7:N7) -> 0 | P7: =IFERROR(O7/COUNTIF(C7:N7,"<>0"),0) -> 0
B8: WiFi・通信費 | C8: ='💰経費・人件費'!B8 | D8: ='💰経費・人件費'!C8 | E8: ='💰経費・人件費'!D8 | F8: ='💰経費・人件費'!E8 | G8: ='💰経費・人件費'!F8 | H8: ='💰経費・人件費'!G8 | I8: ='💰経費・人件費'!H8 | J8: ='💰経費・人件費'!I8 | ... N8: ='💰経費・人件費'!M8 | O8: =SUM(C8:N8) -> 0 | P8: =IFERROR(O8/COUNTIF(C8:N8,"<>0"),0) -> 0
B9: その他経費 | C9: ='💰経費・人件費'!B9 | D9: ='💰経費・人件費'!C9 | E9: ='💰経費・人件費'!D9 | F9: ='💰経費・人件費'!E9 | G9: ='💰経費・人件費'!F9 | H9: ='💰経費・人件費'!G9 | I9: ='💰経費・人件費'!H9 | J9: ='💰経費・人件費'!I9 | ... N9: ='💰経費・人件費'!M9 | O9: =SUM(C9:N9) -> 0 | P9: =IFERROR(O9/COUNTIF(C9:N9,"<>0"),0) -> 0
B10: 経費合計 | C10: =SUM(C5:C9) -> 0 | D10: =SUM(D5:D9) -> 0 | E10: =SUM(E5:E8) -> 0 | F10: =SUM(F5:F8) -> 0 | G10: =SUM(G5:G8) -> 0 | H10: =SUM(H5:H8) -> 0 | I10: =SUM(I5:I8) -> 0 | J10: =SUM(J5:J8) -> 0 | K10: =SUM(K5:K8) -> 0 | L10: =SUM(L5:L8) -> 0 | ... N10: =SUM(N5:N8) -> 0 | O10: =SUM(C10:N10) -> 0 | P10: =IFERROR(O10/COUNTIF(C10:N10,"<>0"),0) -> 0
B11: 人件費（バイト） | C11: ='💰経費・人件費'!B14 -> 22898.333 | D11: ='💰経費・人件費'!C14 -> 4821.6667 | E11: ='💰経費・人件費'!D14 -> 0 | F11: ='💰経費・人件費'!E14 -> 0 | G11: ='💰経費・人件費'!F14 -> 0 | H11: ='💰経費・人件費'!G14 -> 0 | I11: ='💰経費・人件費'!H14 -> 0 | J11: ='💰経費・人件費'!I14 -> 0 | ... N11: ='💰経費・人件費'!M14 -> 0 | O11: =SUM(C11:N11) -> 27720 | P11: =IFERROR(O11/COUNTIF(C11:N11,"<>0"),0) -> 13860
B12: 岡村 稼働時間（参考） | C12: ='💰経費・人件費'!B17 -> 0.25 | D12: ='💰経費・人件費'!C17 -> 0.0625 | E12: ='💰経費・人件費'!D17 -> 0 | F12: ='💰経費・人件費'!E17 -> 0 | G12: ='💰経費・人件費'!F17 -> 0 | H12: ='💰経費・人件費'!G17 -> 0 | I12: ='💰経費・人件費'!H17 -> 0 | J12: ='💰経費・人件費'!I17 -> 0 | ... N12: ='💰経費・人件費'!M17 -> 0 | O12: =SUM(C12:N12) -> 0.3125 | P12: =IFERROR(O12/COUNTIF(C12:N12,"<>0"),0) -> 0.15625
B13: 📌 総経費合計 | C13: =C10+C11 -> 22898.333 | D13: =D10+D11 -> 4821.6667 | E13: =E10+E11 -> 0 | F13: =F10+F11 -> 0 | G13: =G10+G11 -> 0 | H13: =H10+H11 -> 0 | I13: =I10+I11 -> 0 | J13: =J10+J11 -> 0 | ... N13: =N10+N11 -> 0 | O13: =SUM(C13:N13) -> 27720 | P13: =IFERROR(O13/COUNTIF(C13:N13,"<>0"),0) -> 13860
B14: 💹 営業利益 | C14: =C4-C13 -> 357601.67 | D14: =D4-D13 -> 35878.333 | E14: =E4-E13 -> 0 | F14: =F4-F13 -> 0 | G14: =G4-G13 -> 0 | H14: =H4-H13 -> 0 | I14: =I4-I13 -> 0 | J14: =J4-J13 -> 0 | ... O14: =O4-O13 -> 393480 | P14: =IFERROR(O14/COUNTIF(C14:N14,"<>0"),0) -> 196740
B15: 利益率 | C15: =IFERROR(C14/C4,0) -> 0.93982041 | D15: =IFERROR(D14/D4,0) -> 0.88153153 | E15: =IFERROR(E14/E4,0) -> 0 | F15: =IFERROR(F14/F4,0) -> 0 | G15: =IFERROR(G14/G4,0) -> 0 | H15: =IFERROR(H14/H4,0) -> 0 | I15: =IFERROR(I14/I4,0) -> 0 | J15: =IFERROR(J14/J4,0) -> 0 | ... O15: =IFERROR(O14/O4,0) -> 0.93418803 | P15: =IFERROR(O15/COUNTIF(C15:N15,"<>0"),0) -> 0.46709402
B17: 💡 売上は「📊売上入力」から自動反映。経費は「💰経費・人件費」に入力してください。
